Workbook

Sheet MENÚ

Sheet BUSCA_PROD
A12: PRODUCTO: | B12: CABLE DE ENERGIA | E12: MODELO: | F12: =IFERROR(VLOOKUP($B$12,TODO_PROD!$A$13:$K$406,6,FALSE),"NO EXISTE") -> NO EXISTE
A14: CÓDIGO: | B14: =IFERROR(VLOOKUP($B$12,TODO_PROD!$A$13:$K$406,2,FALSE),"NO EXISTE") -> NO EXISTE | E14: SERIE: | F14: =IFERROR(VLOOKUP($B$12,TODO_PROD!$A$13:$K$406,7,FALSE),"NO EXISTE") -> NO EXISTE
A16: CANTIDAD: | B16: =IFERROR(VLOOKUP($B$12,TODO_PROD!$A$13:$K$406,3,FALSE),"NO EXISTE") -> NO EXISTE | E16: UBICACIÓN: | F16: =IFERROR(VLOOKUP($B$12,TODO_PROD!$A$13:$K$406,8,FALSE),"NO EXISTE") -> NO EXISTE
A18: COLOR: | B18: =IFERROR(VLOOKUP($B$12,TODO_PROD!$A$13:$K$406,4,FALSE),"NO EXISTE") -> NO EXISTE | E18: ESTADO: | F18: =IFERROR(VLOOKUP($B$12,TODO_PROD!$A$13:$K$406,9,FALSE),"NO EXISTE") -> NO EXISTE
A20: MARCA: | B20: =IFERROR(VLOOKUP($B$12,TODO_PROD!$A$13:$K$406,5,FALSE),"NO EXISTE") -> NO EXISTE | E20: COSTO: | F20: =IFERROR(VLOOKUP($B$12,TODO_PROD!$A$13:$K$406,11,FALSE),"NO EXISTE") -> NO EXISTE
E22: FECHA: | F22: =IFERROR(VLOOKUP($B$12,TODO_PROD!$A$13:$L$406,12,FALSE),"NO EXISTE") -> NO EXISTE
A24: CARACTERÍSTICAS
A25: =IFERROR(VLOOKUP($B$12,TODO_PROD!$A$13:$K$406,10,FALSE),"NO EXISTE") -> NO EXISTE

Sheet BUSCA_COD
A12: INGRESE CÓDIGO: | B12: RACKCUARTO D | E12: MODELO: | F12: =IFERROR(VLOOKUP($B$12,TODO_COD!$A$13:$K$458,6,FALSE),"NO EXISTE") -> NO EXISTE
A14: PRODUCTO: | B14: =IFERROR(VLOOKUP($B$12,TODO_COD!$A$13:$K$458,3,FALSE),"NO EXISTE") -> NO EXISTE | E14: SERIE: | F14: =IFERROR(VLOOKUP($B$12,TODO_COD!$A$13:$K$458,7,FALSE),"NO EXISTE") -> NO EXISTE
A16: CANTIDAD: | B16: =IFERROR(VLOOKUP($B$12,TODO_COD!$A$13:$K$458,2,FALSE),"NO EXISTE") -> NO EXISTE | E16: UBICACIÓN: | F16: =IFERROR(VLOOKUP($B$12,TODO_COD!$A$13:$K$458,8,FALSE),"NO EXISTE") -> NO EXISTE
A18: COLOR: | B18: =IFERROR(VLOOKUP($B$12,TODO_COD!$A$13:$K$458,4,FALSE),"NO EXISTE") -> NO EXISTE | E18: ESTADO: | F18: =IFERROR(VLOOKUP($B$12,TODO_COD!$A$13:$K$458,9,FALSE),"NO EXISTE") -> NO EXISTE
A20: MARCA: | B20: =IFERROR(VLOOKUP($B$12,TODO_COD!$A$13:$K$458,5,FALSE),"NO EXISTE") -> NO EXISTE | E20: COSTO: | F20: =IFERROR(VLOOKUP($B$12,TODO_COD!$A$13:$K$458,11,FALSE),"NO EXISTE") -> NO EXISTE
E22: FECHA: | F22: =IFERROR(VLOOKUP($B$12,TODO_COD!$A$13:$L$458,12,FALSE),"NO EXISTE") -> NO EXISTE
A24: CARACTERÍSTICAS
A25: =IFERROR(VLOOKUP($B$12,TODO_COD!$A$13:$K$458,10,FALSE),"NO EXISTE") -> NO EXISTE

Sheet EDITABLE
A12: CODIGO | B12: CANTIDAD | C12: PRODUCTO | D12: COLOR | E12: MARCA | F12: MODELO | G12: SERIE | H12: UBICACIÓN | I12: ESTADO | J12: CARACTERISTICAS | K12: COSTO | L12: FECHA
A13: =CONCATENATE(LEFT(C13,4),LEFT(H13,8)) -> CPUAULA-C1 | B13: 1 | C13: CPU | D13: NEGRO | E13: INS | F13: GENERICO | G13: 91225062019 | H13: AULA-C1 | I13: BUENO | J13: WINDOWS 8.1 ENTERPRISE, PROCESADOR: INTEL ® CORE TM i3-9100F CPU, 360 GHZ, RAM 4 GB, 64 BITS, INTERNET ALAMBRICO | K13: 250 | L13: 45288
A14: =CONCATENATE(LEFT(C14,4),LEFT(H14,8)) -> MONIAULA-C1 | B14: 1 | C14: MONITOR | D14: NEGRO | E14: LG | F14: 20MK400H-B | G14: 911NTHM1T121 | H14: AULA-C1 | I14: BUENO | J14: 19,5 PULGADAS, HDMI | K14: 60 | L14: 45288
A15: =CONCATENATE(LEFT(C15,4),LEFT(H15,8)) -> MOUSAULA-C1 | B15: 1 | C15: MOUSE | D15: NEGRO | E15: GENERICO | F15: 5V-100MA | G15: S/S | H15: AULA-C1 | I15: BUENO | J15: ALAMBRICO, LED | K15: 5 | L15: 45288
A16: =CONCATENATE(LEFT(C16,4),LEFT(H16,8)) -> TECLAULA-C1 | B16: 1 | C16: TECLADO | D16: NEGRO | E16: INS | F16: S/M | G16: S/S | H16: AULA-C1 | I16: BUENO | J16: ALAMBRICO, HERGONÓMICO, CONECTOR USB, CON TECLADO NUMÉRICO | K16: 16.7 | L16: 45288
A17: =CONCATENATE(LEFT(C17,4),LEFT(H17,8)) -> PROYAULA-C1 | B17: 1 | C17: PROYECTOR | D17: NEGRO | E17: EPSON | F17: POWER LITE S12+ | G17: PSPK3401963 | H17: AULA-C1 | I17: BUENO | J17: CON PEDESTAL, CABLE VGA DE 15 m. Y CABLE DE ENERGIA | K17: 400 | L17: 45288
A18: =CONCATENATE(LEFT(C18,4),LEFT(H18,8)) -> PARLAULA-C1 | B18: 1 | C18: PARLANTES | D18: NEGRO | E18: KLIP EXTREME | F18: KSS-710 | G18: 13-11580 | H18: AULA-C1 | I18: BUENO | J18: CON SOPORTE AEREO, CABLE DE SONIO DE 20 m. Y CABLE DE ENERGIA, 1 BAJO Y 2 TWITERS | K18: 103 | L18: 45288
A19: =CONCATENATE(LEFT(C19,4),LEFT(H19,8)) -> CAMAAULA-C1 | B19: 1 | C19: CAMARA VIDEO VIGILANCIA | D19: BLANCO | E19: HIKVISION | F19: S/M | G19: S/S | H19: AULA-C1 | I19: BUENO | J19: CONECTADA AL DVR Y VISION EN MOVIL Y CUARTO DE RED | K19: 25 | L19: 44841
A20: =CONCATENATE(LEFT(C20,4),LEFT(H20,8)) -> SENSAULA-C1 | B20: 1 | C20: SENSOR DE ALARMA | D20: BLANCO | E20: DSC | F20: LC-100PI | G20: 88030080 | H20: AULA-C1 | I20: BUENO | J20: CONECTADA AL SISTEMA DE ALARMAS | K20: 20 | L20: 44841
A21: =CONCATENATE(LEFT(C21,4),LEFT(H21,8))
A22: =CONCATENATE(LEFT(C22,4),LEFT(H22,8))
A23: =CONCATENATE(LEFT(C23,4),LEFT(H23,8))
A24: CODIGO | B24: CANTIDAD | C24: PRODUCTO | D24: COLOR | E24: MARCA | F24: MODELO | G24: SERIE | H24: UBICACIÓN | I24: ESTADO | J24: CARACTERISTICAS | K24: COSTO | L24: FECHA
A25: =CONCATENATE(LEFT(C25,4),LEFT(H25,8)) -> CPUAULA-C2 | B25: 1 | C25: CPU | D25: NEGRO | E25: INS | F25: GENERICO | G25: 91225062019 | H25: AULA-C2 | I25: BUENO | J25: WINDOWS 8.1 ENTERPRISE, PROCESADOR: INTEL ® CORE TM i3-9100F CPU, 360 GHZ, RAM 4 GB, 64 BITS, INTERNET ALAMBRICO | K25: 250 | L25: 45288
A26: =CONCATENATE(LEFT(C26,4),LEFT(H26,8)) -> MONIAULA-C2 | B26: 1 | C26: MONITOR | D26: NEGRO | E26: LG | F26: 20MK400H-B | G26: 911NTNH1S119 | H26: AULA-C2 | I26: BUENO | J26: 19,5 PULGADAS, HDMI | K26: 60 | L26: 45288
A27: =CONCATENATE(LEFT(C27,4),LEFT(H27,8)) -> MOUSAULA-C2 | B27: 1 | C27: MOUSE | D27: NEGRO | E27: GENIUS | F27: GM-04011P | G27: 124430707394 | H27: AULA-C2 | I27: BUENO | J27: ALAMBRICO, LED, DISEÑO ERGONÓMICO | K27: 6 | L27: 45288
A28: =CONCATENATE(LEFT(C28,4),LEFT(H28,8)) -> TECLAULA-C2 | B28: 1 | C28: TECLADO | D28: NEGRO | E28: INS | F28: S/M | G28: S/S | H28: AULA-C2 | I28: BUENO | J28: ALAMBRICO, HERGONÓMICO, CONECTOR USB, CON TECLADO NUMÉRICO | K28: 16.7 | L28: 45288
A29: =CONCATENATE(LEFT(C29,4),LEFT(H29,8)) -> PROYAULA-C2 | B29: 1 | C29: PROYECTOR | D29: NEGRO | E29: EPSON | F29: POWER LITE S12+ | G29: PSPK3401919 | H29: AULA-C2 | I29: BUENO | J29: CON PEDESTAL, CABLE VGA DE 15 m. Y CABLE DE ENERGIA | K29: 400 | L29: 45288
A30: =CONCATENATE(LEFT(C30,4),LEFT(H30,8)) -> PARLAULA-C2 | B30: 1 | C30: PARLANTES | D30: NEGRO | E30: KLIP EXTREME | F30: KSS-710 | G30: 13-1158005 | H30: AULA-C2 | I30: BUENO | J30: CON SOPORTE AEREO, CABLE DE SONIO DE 20 m. Y CABLE DE ENERGIA, 1 BAJO Y 2 TWITERS | K30: 103 | L30: 45288
A31: =CONCATENATE(LEFT(C31,4),LEFT(H31,8)) -> CAMAAULA-C2 | B31: 1 | C31: CAMARA VIDEO VIGILANCIA | D31: BLANCO | E31: HIKVISION | F31: S/M | G31: S/S | H31: AULA-C2 | I31: BUENO | J31: CONECTADA AL DVR Y VISION EN MOVIL Y CUARTO DE RED | K31: 25 | L31: 44841
A32: =CONCATENATE(LEFT(C32,4),LEFT(H32,8)) -> SENSAULA-C2 | B32: 1 | C32: SENSOR DE ALARMA | D32: BLANCO | E32: DSC | F32: LC-100PI | G32: 88030080 | H32: AULA-C2 | I32: BUENO | J32: CONECTADA AL SISTEMA DE ALARMAS | K32: 20 | L32: 44841
A33: =CONCATENATE(LEFT(C33,4),LEFT(H33,8)) -> SWITAULA-C2 | B33: 1 | C33: SWITCH DE INTERNET | D33: AZUL | E33: T-PLINK | F33: TN-SG108 | G33: 22361E5003891 | H33: AULA-C2 | I33: BUENO | J33: DE 5 PUERTOS RJ45, TIPO DE COMUNICACIÓN STORE AND FORWARD | K33: 22 | L33: 45288
A34: =CONCATENATE(LEFT(C34,4),LEFT(H34,8)) -> REGUAULA-C2 | B34: 1 | C34: REGULADOR DE VOLTAJE | D34: NEGRO | E34: INS | F34: AVR-INS2000VA | G34: 19C04206300 | H34: AULA-C2 | I34: BUENO | J34: DE 8 TOMAS, 120V-60HZ, 2 PUERTOS RJ11 PARA TELÉFONO | K34: 15 | L34: 45288
A35: =CONCATENATE(LEFT(C35,4),LEFT(H35,8))
A36: =CONCATENATE(LEFT(C36,4),LEFT(H36,8))
A37: =CONCATENATE(LEFT(C37,4),LEFT(H37,8))
A38: CODIGO | B38: CANTIDAD | C38: PRODUCTO | D38: COLOR | E38: MARCA | F38: MODELO | G38: SERIE | H38: UBICACIÓN | I38: ESTADO | J38: CARACTERISTICAS | K38: COSTO | L38: FECHA
A39: =CONCATENATE(LEFT(C39,4),LEFT(H39,8)) -> CPUAULA-C3 | B39: 1 | C39: CPU | D39: NEGRO | E39: DELUX | F39: S/M | G39: S/S | H39: AULA-C3 | I39: BUENO | J39: WINDOWS 8.1 ENTERPRISE, PROCESADOR: INTEL ® CORE TM i5-2310 CPU, 2.90 GHZ, RAM 4 GB, 64 BITS, INTERNET ALAMBRICO | K39: 250 | L39: 45288
A40: =CONCATENATE(LEFT(C40,4),LEFT(H40,8)) -> MONIAULA-C3 | B40: 1 | C40: MONITOR | D40: NEGRO | E40: HP | F40: HPLV1911 | G40: 6CM213011T | H40: AULA-C3 | I40: BUENO | J40: 19,5 PULGADAS | K40: 100 | L40: 45288
A41: =CONCATENATE(LEFT(C41,4),LEFT(H41,8)) -> MOUSAULA-C3 | B41: 1 | C41: MOUSE | D41: NEGRO, TRASPARENTE | E41: INS | F41: S/M | G41: S/S | H41: AULA-C3 | I41: BUENO | J41: ALAMBRICO, LED, OPTICO | K41: 5 | L41: 45288
A42: =CONCATENATE(LEFT(C42,4),LEFT(H42,8)) -> TECLAULA-C3 | B42: 1 | C42: TECLADO | D42: NEGRO | E42: GENERICO | F42: S/M | G42: S/S | H42: AULA-C3 | I42: BUENO | J42: ALAMBRICO, TECLADO ALFANUMÉRICO, TECLAS ESPECIALES, CONECCIÓN USB. | K42: 12 | L42: 45288
A43: =CONCATENATE(LEFT(C43,4),LEFT(H43,8)) -> PROYAULA-C3 | B43: 1 | C43: PROYECTOR | D43: NEGRO | E43: EPSON | F43: POWER LITE S12+ | G43: PSPK2308028 | H43: AULA-C3 | I43: BUENO | J43: CON PEDESTAL, CABLE VGA DE 15 m. Y CABLE DE ENERGIA | K43: 400 | L43: 45288
A44: =CONCATENATE(LEFT(C44,4),LEFT(H44,8)) -> PARLAULA-C3 | B44: 1 | C44: PARLANTES | D44: NEGRO | E44: KLIP EXTREME | F44: KSS-710 | G44: 13-11580 | H44: AULA-C3 | I44: BUENO | J44: CON SOPORTE AEREO, CABLE DE SONIO DE 20 m. Y CABLE DE ENERGIA, 1 BAJO Y 2 TWITERS | K44: 103 | L44: 45288
A45: =CONCATENATE(LEFT(C45,4),LEFT(H45,8)) -> CAMAAULA-C3 | B45: 1 | C45: CAMARA VIDEO VIGILANCIA | D45: BLANCO | E45: HIKVISION | F45: S/M | G45: S/S | H45: AULA-C3 | I45: BUENO | J45: CONECTADA AL DVR Y VISION EN MOVIL Y CUARTO DE RED | K45: 25 | L45: 44841
A46: =CONCATENATE(LEFT(C46,4),LEFT(H46,8)) -> SENSAULA-C3 | B46: 1 | C46: SENSOR DE ALARMA | D46: BLANCO | E46: DSC | F46: LC-100PI | G46: 88030080 | H46: AULA-C3 | I46: BUENO | J46: CONECTADA AL SISTEMA DE ALARMAS | K46: 20 | L46: 44841
A47: =CONCATENATE(LEFT(C47,4),LEFT(H47,8))
A48: =CONCATENATE(LEFT(C48,4),LEFT(H48,8))
A49: =CONCATENATE(LEFT(C49,4),LEFT(H49,8))
A50: CODIGO | B50: CANTIDAD | C50: PRODUCTO | D50: COLOR | E50: MARCA | F50: MODELO | G50: SERIE | H50: UBICACIÓN | I50: ESTADO | J50: CARACTERISTICAS | K50: COSTO | L50: FECHA
A51: =CONCATENATE(LEFT(C51,4),LEFT(H51,8)) -> CPUAULA-E2 | B51: 1 | C51: CPU | D51: NEGRO | E51: SION | F51: PC-SION-COE I5-SAM20 | G51: 81834 | H51: AULA-E2 | I51: BUENO | J51: WINDOWS 8.1 SINGLE LENGUAGE, PROCESADOR: INTEL ® CORE TM i5-4460 CPU, 3.20 GHZ, RAM 4 GB, 64 BITS, INTERNET ALAMBRICO | K51: 250 | L51: 45288
...

Sheet TODO_PROD
A12: =+EDITABLE!$C$12 -> PRODUCTO | B12: =+EDITABLE!$A$12 -> CODIGO | C12: =+EDITABLE!$B$12 -> CANTIDAD | D12: =+EDITABLE!$D$12 -> COLOR | E12: =+EDITABLE!$E$12 -> MARCA | F12: =+EDITABLE!$F$12 -> MODELO | G12: =+EDITABLE!$G$12 -> SERIE | H12: =+EDITABLE!$H$12 -> UBICACIÓN | I12: =+EDITABLE!$I$12 -> ESTADO | J12: =+EDITABLE!$J$12 -> CARACTERISTICAS | K12: =+EDITABLE!$K$12 -> COSTO | L12: FECHA
A13: =CONCATENATE(+EDITABLE!C13," ",H13) -> CPU AULA-C1 | B13: =+EDITABLE!A13 -> CPUAULA-C1 | C13: =+EDITABLE!B13 -> 1 | D13: =+EDITABLE!D13 -> NEGRO | E13: =+EDITABLE!E13 -> INS | F13: =+EDITABLE!F13 -> GENERICO | G13: =+EDITABLE!G13 -> 91225062019 | H13: =+EDITABLE!H13 -> AULA-C1 | I13: =+EDITABLE!I13 -> BUENO | J13: =+EDITABLE!J13 -> WINDOWS 8.1 ENTERPRISE, PROCESADOR: INTEL ® CORE TM i3-9100F CPU, 360 GHZ, RAM 4 GB, 64 BITS, INTERNET ALAMBRICO | K13: =+EDITABLE!K13 -> 250 | L13: =+EDITABLE!L13 -> 45288 | M13: 1
A14: =CONCATENATE(+EDITABLE!C14," ",H14) -> MONITOR AULA-C1 | B14: =+EDITABLE!A14 -> MONIAULA-C1 | C14: =+EDITABLE!B14 -> 1 | D14: =+EDITABLE!D14 -> NEGRO | E14: =+EDITABLE!E14 -> LG | F14: =+EDITABLE!F14 -> 20MK400H-B | G14: =+EDITABLE!G14 -> 911NTHM1T121 | H14: =+EDITABLE!H14 -> AULA-C1 | I14: =+EDITABLE!I14 -> BUENO | J14: =+EDITABLE!J14 -> 19,5 PULGADAS, HDMI | K14: =+EDITABLE!K14 -> 60 | L14: =+EDITABLE!L14 -> 45288
A15: =CONCATENATE(+EDITABLE!C15," ",H15) -> MOUSE AULA-C1 | B15: =+EDITABLE!A15 -> MOUSAULA-C1 | C15: =+EDITABLE!B15 -> 1 | D15: =+EDITABLE!D15 -> NEGRO | E15: =+EDITABLE!E15 -> GENERICO | F15: =+EDITABLE!F15 -> 5V-100MA | G15: =+EDITABLE!G15 -> S/S | H15: =+EDITABLE!H15 -> AULA-C1 | I15: =+EDITABLE!I15 -> BUENO | J15: =+EDITABLE!J15 -> ALAMBRICO, LED | K15: =+EDITABLE!K15 -> 5 | L15: =+EDITABLE!L15 -> 45288
A16: =CONCATENATE(+EDITABLE!C16," ",H16) -> TECLADO AULA-C1 | B16: =+EDITABLE!A16 -> TECLAULA-C1 | C16: =+EDITABLE!B16 -> 1 | D16: =+EDITABLE!D16 -> NEGRO | E16: =+EDITABLE!E16 -> INS | F16: =+EDITABLE!F16 -> S/M | G16: =+EDITABLE!G16 -> S/S | H16: =+EDITABLE!H16 -> AULA-C1 | I16: =+EDITABLE!I16 -> BUENO | J16: =+EDITABLE!J16 -> ALAMBRICO, HERGONÓMICO, CONECTOR USB, CON TECLADO NUMÉRICO | K16: =+EDITABLE!K16 -> 16.7 | L16: =+EDITABLE!L16 -> 45288
A17: =CONCATENATE(+EDITABLE!C17," ",H17) -> PROYECTOR AULA-C1 | B17: =+EDITABLE!A17 -> PROYAULA-C1 | C17: =+EDITABLE!B17 -> 1 | D17: =+EDITABLE!D17 -> NEGRO | E17: =+EDITABLE!E17 -> EPSON | F17: =+EDITABLE!F17 -> POWER LITE S12+ | G17: =+EDITABLE!G17 -> PSPK3401963 | H17: =+EDITABLE!H17 -> AULA-C1 | I17: =+EDITABLE!I17 -> BUENO | J17: =+EDITABLE!J17 -> CON PEDESTAL, CABLE VGA DE 15 m. Y CABLE DE ENERGIA | K17: =+EDITABLE!K17 -> 400 | L17: =+EDITABLE!L17 -> 45288
A18: =CONCATENATE(+EDITABLE!C18," ",H18) -> PARLANTES AULA-C1 | B18: =+EDITABLE!A18 -> PARLAULA-C1 | C18: =+EDITABLE!B18 -> 1 | D18: =+EDITABLE!D18 -> NEGRO | E18: =+EDITABLE!E18 -> KLIP EXTREME | F18: =+EDITABLE!F18 -> KSS-710 | G18: =+EDITABLE!G18 -> 13-11580 | H18: =+EDITABLE!H18 -> AULA-C1 | I18: =+EDITABLE!I18 -> BUENO | J18: =+EDITABLE!J18 -> CON SOPORTE AEREO, CABLE DE SONIO DE 20 m. Y CABLE DE ENERGIA, 1 BAJO Y 2 TWITERS | K18: =+EDITABLE!K18 -> 103 | L18: =+EDITABLE!L18 -> 45288
A19: =CONCATENATE(+EDITABLE!C19," ",H19) -> CAMARA VIDEO VIGILANCIA AULA-C1 | B19: =+EDITABLE!A19 -> CAMAAULA-C1 | C19: =+EDITABLE!B19 -> 1 | D19: =+EDITABLE!D19 -> BLANCO | E19: =+EDITABLE!E19 -> HIKVISION | F19: =+EDITABLE!F19 -> S/M | G19: =+EDITABLE!G19 -> S/S | H19: =+EDITABLE!H19 -> AULA-C1 | I19: =+EDITABLE!I19 -> BUENO | J19: =+EDITABLE!J19 -> CONECTADA AL DVR Y VISION EN MOVIL Y CUARTO DE RED | K19: =+EDITABLE!K19 -> 25 | L19: =+EDITABLE!L19 -> 44841
A20: =CONCATENATE(+EDITABLE!C20," ",H20) -> SENSOR DE ALARMA AULA-C1 | B20: =+EDITABLE!A20 -> SENSAULA-C1 | C20: =+EDITABLE!B20 -> 1 | D20: =+EDITABLE!D20 -> BLANCO | E20: =+EDITABLE!E20 -> DSC | F20: =+EDITABLE!F20 -> LC-100PI | G20: =+EDITABLE!G20 -> 88030080 | H20: =+EDITABLE!H20 -> AULA-C1 | I20: =+EDITABLE!I20 -> BUENO | J20: =+EDITABLE!J20 -> CONECTADA AL SISTEMA DE ALARMAS | K20: =+EDITABLE!K20 -> 20 | L20: =+EDITABLE!L20 -> 44841
A21: =CONCATENATE(+EDITABLE!C21," ",H21) -> 0 | B21: =+EDITABLE!A21 | C21: =+EDITABLE!B21 -> 0 | D21: =+EDITABLE!D21 -> 0 | E21: =+EDITABLE!E21 -> 0 | F21: =+EDITABLE!F21 -> 0 | G21: =+EDITABLE!G21 -> 0 | H21: =+EDITABLE!H21 -> 0 | I21: =+EDITABLE!I21 -> 0 | J21: =+EDITABLE!J21 -> 0 | K21: =+EDITABLE!K21 -> 0 | L21: =+EDITABLE!L21 -> 0
A22: =CONCATENATE(+EDITABLE!C22," ",H22) -> 0 | B22: =+EDITABLE!A22 | C22: =+EDITABLE!B22 -> 0 | D22: =+EDITABLE!D22 -> 0 | E22: =+EDITABLE!E22 -> 0 | F22: =+EDITABLE!F22 -> 0 | G22: =+EDITABLE!G22 -> 0 | H22: =+EDITABLE!H22 -> 0 | I22: =+EDITABLE!I22 -> 0 | J22: =+EDITABLE!J22 -> 0 | K22: =+EDITABLE!K22 -> 0 | L22: =+EDITABLE!L22 -> 0
A23: =CONCATENATE(+EDITABLE!C23," ",H23) -> 0 | B23: =+EDITABLE!A23 | C23: =+EDITABLE!B23 -> 0 | D23: =+EDITABLE!D23 -> 0 | E23: =+EDITABLE!E23 -> 0 | F23: =+EDITABLE!F23 -> 0 | G23: =+EDITABLE!G23 -> 0 | H23: =+EDITABLE!H23 -> 0 | I23: =+EDITABLE!I23 -> 0 | J23: =+EDITABLE!J23 -> 0 | K23: =+EDITABLE!K23 -> 0 | L23: =+EDITABLE!L23 -> 0
A24: =CONCATENATE(+EDITABLE!C25," ",H24) -> CPU AULA-C2 | B24: =+EDITABLE!A25 -> CPUAULA-C2 | C24: =+EDITABLE!B25 -> 1 | D24: =+EDITABLE!D25 -> NEGRO | E24: =+EDITABLE!E25 -> INS | F24: =+EDITABLE!F25 -> GENERICO | G24: =+EDITABLE!G25 -> 91225062019 | H24: =+EDITABLE!H25 -> AULA-C2 | I24: =+EDITABLE!I25 -> BUENO | J24: =+EDITABLE!J25 -> WINDOWS 8.1 ENTERPRISE, PROCESADOR: INTEL ® CORE TM i3-9100F CPU, 360 GHZ, RAM 4 GB, 64 BITS, INTERNET ALAMBRICO | K24: =+EDITABLE!K25 -> 250 | L24: =+EDITABLE!L25 -> 45288 | M24: 2
A25: =CONCATENATE(+EDITABLE!C26," ",H25) -> MONITOR AULA-C2 | B25: =+EDITABLE!A26 -> MONIAULA-C2 | C25: =+EDITABLE!B26 -> 1 | D25: =+EDITABLE!D26 -> NEGRO | E25: =+EDITABLE!E26 -> LG | F25: =+EDITABLE!F26 -> 20MK400H-B | G25: =+EDITABLE!G26 -> 911NTNH1S119 | H25: =+EDITABLE!H26 -> AULA-C2 | I25: =+EDITABLE!I26 -> BUENO | J25: =+EDITABLE!J26 -> 19,5 PULGADAS, HDMI | K25: =+EDITABLE!K26 -> 60 | L25: =+EDITABLE!L26 -> 45288
A26: =CONCATENATE(+EDITABLE!C27," ",H26) -> MOUSE AULA-C2 | B26: =+EDITABLE!A27 -> MOUSAULA-C2 | C26: =+EDITABLE!B27 -> 1 | D26: =+EDITABLE!D27 -> NEGRO | E26: =+EDITABLE!E27 -> GENIUS | F26: =+EDITABLE!F27 -> GM-04011P | G26: =+EDITABLE!G27 -> 124430707394 | H26: =+EDITABLE!H27 -> AULA-C2 | I26: =+EDITABLE!I27 -> BUENO | J26: =+EDITABLE!J27 -> ALAMBRICO, LED, DISEÑO ERGONÓMICO | K26: =+EDITABLE!K27 -> 6 | L26: =+EDITABLE!L27 -> 45288
A27: =CONCATENATE(+EDITABLE!C28," ",H27) -> TECLADO AULA-C2 | B27: =+EDITABLE!A28 -> TECLAULA-C2 | C27: =+EDITABLE!B28 -> 1 | D27: =+EDITABLE!D28 -> NEGRO | E27: =+EDITABLE!E28 -> INS | F27: =+EDITABLE!F28 -> S/M | G27: =+EDITABLE!G28 -> S/S | H27: =+EDITABLE!H28 -> AULA-C2 | I27: =+EDITABLE!I28 -> BUENO | J27: =+EDITABLE!J28 -> ALAMBRICO, HERGONÓMICO, CONECTOR USB, CON TECLADO NUMÉRICO | K27: =+EDITABLE!K28 -> 16.7 | L27: =+EDITABLE!L28 -> 45288
A28: =CONCATENATE(+EDITABLE!C29," ",H28) -> PROYECTOR AULA-C2 | B28: =+EDITABLE!A29 -> PROYAULA-C2 | C28: =+EDITABLE!B29 -> 1 | D28: =+EDITABLE!D29 -> NEGRO | E28: =+EDITABLE!E29 -> EPSON | F28: =+EDITABLE!F29 -> POWER LITE S12+ | G28: =+EDITABLE!G29 -> PSPK3401919 | H28: =+EDITABLE!H29 -> AULA-C2 | I28: =+EDITABLE!I29 -> BUENO | J28: =+EDITABLE!J29 -> CON PEDESTAL, CABLE VGA DE 15 m. Y CABLE DE ENERGIA | K28: =+EDITABLE!K29 -> 400 | L28: =+EDITABLE!L29 -> 45288
A29: =CONCATENATE(+EDITABLE!C30," ",H29) -> PARLANTES AULA-C2 | B29: =+EDITABLE!A30 -> PARLAULA-C2 | C29: =+EDITABLE!B30 -> 1 | D29: =+EDITABLE!D30 -> NEGRO | E29: =+EDITABLE!E30 -> KLIP EXTREME | F29: =+EDITABLE!F30 -> KSS-710 | G29: =+EDITABLE!G30 -> 13-1158005 | H29: =+EDITABLE!H30 -> AULA-C2 | I29: =+EDITABLE!I30 -> BUENO | J29: =+EDITABLE!J30 -> CON SOPORTE AEREO, CABLE DE SONIO DE 20 m. Y CABLE DE ENERGIA, 1 BAJO Y 2 TWITERS | K29: =+EDITABLE!K30 -> 103 | L29: =+EDITABLE!L30 -> 45288
A30: =CONCATENATE(+EDITABLE!C31," ",H30) -> CAMARA VIDEO VIGILANCIA AULA-C2 | B30: =+EDITABLE!A31 -> CAMAAULA-C2 | C30: =+EDITABLE!B31 -> 1 | D30: =+EDITABLE!D31 -> BLANCO | E30: =+EDITABLE!E31 -> HIKVISION | F30: =+EDITABLE!F31 -> S/M | G30: =+EDITABLE!G31 -> S/S | H30: =+EDITABLE!H31 -> AULA-C2 | I30: =+EDITABLE!I31 -> BUENO | J30: =+EDITABLE!J31 -> CONECTADA AL DVR Y VISION EN MOVIL Y CUARTO DE RED | K30: =+EDITABLE!K31 -> 25 | L30: =+EDITABLE!L31 -> 44841
A31: =CONCATENATE(+EDITABLE!C32," ",H31) -> SENSOR DE ALARMA AULA-C2 | B31: =+EDITABLE!A32 -> SENSAULA-C2 | C31: =+EDITABLE!B32 -> 1 | D31: =+EDITABLE!D32 -> BLANCO | E31: =+EDITABLE!E32 -> DSC | F31: =+EDITABLE!F32 -> LC-100PI | G31: =+EDITABLE!G32 -> 88030080 | H31: =+EDITABLE!H32 -> AULA-C2 | I31: =+EDITABLE!I32 -> BUENO | J31: =+EDITABLE!J32 -> CONECTADA AL SISTEMA DE ALARMAS | K31: =+EDITABLE!K32 -> 20 | L31: =+EDITABLE!L32 -> 44841
A32: =CONCATENATE(+EDITABLE!C33," ",H32) -> SWITCH DE INTERNET AULA-C2 | B32: =+EDITABLE!A33 -> SWITAULA-C2 | C32: =+EDITABLE!B33 -> 1 | D32: =+EDITABLE!D33 -> AZUL | E32: =+EDITABLE!E33 -> T-PLINK | F32: =+EDITABLE!F33 -> TN-SG108 | G32: =+EDITABLE!G33 -> 22361E5003891 | H32: =+EDITABLE!H33 -> AULA-C2 | I32: =+EDITABLE!I33 -> BUENO | J32: =+EDITABLE!J33 -> DE 5 PUERTOS RJ45, TIPO DE COMUNICACIÓN STORE AND FORWARD | K32: =+EDITABLE!K33 -> 22 | L32: =+EDITABLE!L33 -> 45288
A33: =CONCATENATE(+EDITABLE!C34," ",H33) -> REGULADOR DE VOLTAJE AULA-C2 | B33: =+EDITABLE!A34 -> REGUAULA-C2 | C33: =+EDITABLE!B34 -> 1 | D33: =+EDITABLE!D34 -> NEGRO | E33: =+EDITABLE!E34 -> INS | F33: =+EDITABLE!F34 -> AVR-INS2000VA | G33: =+EDITABLE!G34 -> 19C04206300 | H33: =+EDITABLE!H34 -> AULA-C2 | I33: =+EDITABLE!I34 -> BUENO | J33: =+EDITABLE!J34 -> DE 8 TOMAS, 120V-60HZ, 2 PUERTOS RJ11 PARA TELÉFONO | K33: =+EDITABLE!K34 -> 15 | L33: =+EDITABLE!L34 -> 45288
A34: =CONCATENATE(+EDITABLE!C35," ",H34) -> 0 | B34: =+EDITABLE!A35 | C34: =+EDITABLE!B35 -> 0 | D34: =+EDITABLE!D35 -> 0 | E34: =+EDITABLE!E35 -> 0 | F34: =+EDITABLE!F35 -> 0 | G34: =+EDITABLE!G35 -> 0 | H34: =+EDITABLE!H35 -> 0 | I34: =+EDITABLE!I35 -> 0 | J34: =+EDITABLE!J35 -> 0 | K34: =+EDITABLE!K35 -> 0 | L34: =+EDITABLE!L35 -> 0
A35: =CONCATENATE(+EDITABLE!C36," ",H35) -> 0 | B35: =+EDITABLE!A36 | C35: =+EDITABLE!B36 -> 0 | D35: =+EDITABLE!D36 -> 0 | E35: =+EDITABLE!E36 -> 0 | F35: =+EDITABLE!F36 -> 0 | G35: =+EDITABLE!G36 -> 0 | H35: =+EDITABLE!H36 -> 0 | I35: =+EDITABLE!I36 -> 0 | J35: =+EDITABLE!J36 -> 0 | K35: =+EDITABLE!K36 -> 0 | L35: =+EDITABLE!L36 -> 0
A36: =CONCATENATE(+EDITABLE!C37," ",H36) -> 0 | B36: =+EDITABLE!A37 | C36: =+EDITABLE!B37 -> 0 | D36: =+EDITABLE!D37 -> 0 | E36: =+EDITABLE!E37 -> 0 | F36: =+EDITABLE!F37 -> 0 | G36: =+EDITABLE!G37 -> 0 | H36: =+EDITABLE!H37 -> 0 | I36: =+EDITABLE!I37 -> 0 | J36: =+EDITABLE!J37 -> 0 | K36: =+EDITABLE!K37 -> 0 | L36: =+EDITABLE!L37 -> 0
A37: =CONCATENATE(+EDITABLE!C39," ",H37) -> CPU AULA-C3 | B37: =+EDITABLE!A39 -> CPUAULA-C3 | C37: =+EDITABLE!B39 -> 1 | D37: =+EDITABLE!D39 -> NEGRO | E37: =+EDITABLE!E39 -> DELUX | F37: =+EDITABLE!F39 -> S/M | G37: =+EDITABLE!G39 -> S/S | H37: =+EDITABLE!H39 -> AULA-C3 | I37: =+EDITABLE!I39 -> BUENO | J37: =+EDITABLE!J39 -> WINDOWS 8.1 ENTERPRISE, PROCESADOR: INTEL ® CORE TM i5-2310 CPU, 2.90 GHZ, RAM 4 GB, 64 BITS, INTERNET ALAMBRICO | K37: =+EDITABLE!K39 -> 250 | L37: =+EDITABLE!L39 -> 45288 | M37: 3
A38: =CONCATENATE(+EDITABLE!C40," ",H38) -> MONITOR AULA-C3 | B38: =+EDITABLE!A40 -> MONIAULA-C3 | C38: =+EDITABLE!B40 -> 1 | D38: =+EDITABLE!D40 -> NEGRO | E38: =+EDITABLE!E40 -> HP | F38: =+EDITABLE!F40 -> HPLV1911 | G38: =+EDITABLE!G40 -> 6CM213011T | H38: =+EDITABLE!H40 -> AULA-C3 | I38: =+EDITABLE!I40 -> BUENO | J38: =+EDITABLE!J40 -> 19,5 PULGADAS | K38: =+EDITABLE!K40 -> 100 | L38: =+EDITABLE!L40 -> 45288
A39: =CONCATENATE(+EDITABLE!C41," ",H39) -> MOUSE AULA-C3 | B39: =+EDITABLE!A41 -> MOUSAULA-C3 | C39: =+EDITABLE!B41 -> 1 | D39: =+EDITABLE!D41 -> NEGRO, TRASPARENTE | E39: =+EDITABLE!E41 -> INS | F39: =+EDITABLE!F41 -> S/M | G39: =+EDITABLE!G41 -> S/S | H39: =+EDITABLE!H41 -> AULA-C3 | I39: =+EDITABLE!I41 -> BUENO | J39: =+EDITABLE!J41 -> ALAMBRICO, LED, OPTICO | K39: =+EDITABLE!K41 -> 5 | L39: =+EDITABLE!L41 -> 45288
A40: =CONCATENATE(+EDITABLE!C42," ",H40) -> TECLADO AULA-C3 | B40: =+EDITABLE!A42 -> TECLAULA-C3 | C40: =+EDITABLE!B42 -> 1 | D40: =+EDITABLE!D42 -> NEGRO | E40: =+EDITABLE!E42 -> GENERICO | F40: =+EDITABLE!F42 -> S/M | G40: =+EDITABLE!G42 -> S/S | H40: =+EDITABLE!H42 -> AULA-C3 | I40: =+EDITABLE!I42 -> BUENO | J40: =+EDITABLE!J42 -> ALAMBRICO, TECLADO ALFANUMÉRICO, TECLAS ESPECIALES, CONECCIÓN USB. | K40: =+EDITABLE!K42 -> 12 | L40: =+EDITABLE!L42 -> 45288
A41: =CONCATENATE(+EDITABLE!C43," ",H41) -> PROYECTOR AULA-C3 | B41: =+EDITABLE!A43 -> PROYAULA-C3 | C41: =+EDITABLE!B43 -> 1 | D41: =+EDITABLE!D43 -> NEGRO | E41: =+EDITABLE!E43 -> EPSON | F41: =+EDITABLE!F43 -> POWER LITE S12+ | G41: =+EDITABLE!G43 -> PSPK2308028 | H41: =+EDITABLE!H43 -> AULA-C3 | I41: =+EDITABLE!I43 -> BUENO | J41: =+EDITABLE!J43 -> CON PEDESTAL, CABLE VGA DE 15 m. Y CABLE DE ENERGIA | K41: =+EDITABLE!K43 -> 400 | L41: =+EDITABLE!L43 -> 45288
A42: =CONCATENATE(+EDITABLE!C44," ",H42) -> PARLANTES AULA-C3 | B42: =+EDITABLE!A44 -> PARLAULA-C3 | C42: =+EDITABLE!B44 -> 1 | D42: =+EDITABLE!D44 -> NEGRO | E42: =+EDITABLE!E44 -> KLIP EXTREME | F42: =+EDITABLE!F44 -> KSS-710 | G42: =+EDITABLE!G44 -> 13-11580 | H42: =+EDITABLE!H44 -> AULA-C3 | I42: =+EDITABLE!I44 -> BUENO | J42: =+EDITABLE!J44 -> CON SOPORTE AEREO, CABLE DE SONIO DE 20 m. Y CABLE DE ENERGIA, 1 BAJO Y 2 TWITERS | K42: =+EDITABLE!K44 -> 103 | L42: =+EDITABLE!L44 -> 45288
A43: =CONCATENATE(+EDITABLE!C45," ",H43) -> CAMARA VIDEO VIGILANCIA AULA-C3 | B43: =+EDITABLE!A45 -> CAMAAULA-C3 | C43: =+EDITABLE!B45 -> 1 | D43: =+EDITABLE!D45 -> BLANCO | E43: =+EDITABLE!E45 -> HIKVISION | F43: =+EDITABLE!F45 -> S/M | G43: =+EDITABLE!G45 -> S/S | H43: =+EDITABLE!H45 -> AULA-C3 | I43: =+EDITABLE!I45 -> BUENO | J43: =+EDITABLE!J45 -> CONECTADA AL DVR Y VISION EN MOVIL Y CUARTO DE RED | K43: =+EDITABLE!K45 -> 25 | L43: =+EDITABLE!L45 -> 44841
A44: =CONCATENATE(+EDITABLE!C46," ",H44) -> SENSOR DE ALARMA AULA-C3 | B44: =+EDITABLE!A46 -> SENSAULA-C3 | C44: =+EDITABLE!B46 -> 1 | D44: =+EDITABLE!D46 -> BLANCO | E44: =+EDITABLE!E46 -> DSC | F44: =+EDITABLE!F46 -> LC-100PI | G44: =+EDITABLE!G46 -> 88030080 | H44: =+EDITABLE!H46 -> AULA-C3 | I44: =+EDITABLE!I46 -> BUENO | J44: =+EDITABLE!J46 -> CONECTADA AL SISTEMA DE ALARMAS | K44: =+EDITABLE!K46 -> 20 | L44: =+EDITABLE!L46 -> 44841
A45: =CONCATENATE(+EDITABLE!C47," ",H45) -> 0 | B45: =+EDITABLE!A47 | C45: =+EDITABLE!B47 -> 0 | D45: =+EDITABLE!D47 -> 0 | E45: =+EDITABLE!E47 -> 0 | F45: =+EDITABLE!F47 -> 0 | G45: =+EDITABLE!G47 -> 0 | H45: =+EDITABLE!H47 -> 0 | I45: =+EDITABLE!I47 -> 0 | J45: =+EDITABLE!J47 -> 0 | K45: =+EDITABLE!K47 -> 0 | L45: =+EDITABLE!L47 -> 0
A46: =CONCATENATE(+EDITABLE!C48," ",H46) -> 0 | B46: =+EDITABLE!A48 | C46: =+EDITABLE!B48 -> 0 | D46: =+EDITABLE!D48 -> 0 | E46: =+EDITABLE!E48 -> 0 | F46: =+EDITABLE!F48 -> 0 | G46: =+EDITABLE!G48 -> 0 | H46: =+EDITABLE!H48 -> 0 | I46: =+EDITABLE!I48 -> 0 | J46: =+EDITABLE!J48 -> 0 | K46: =+EDITABLE!K48 -> 0 | L46: =+EDITABLE!L48 -> 0
A47: =CONCATENATE(+EDITABLE!C49," ",H47) -> 0 | B47: =+EDITABLE!A49 | C47: =+EDITABLE!B49 -> 0 | D47: =+EDITABLE!D49 -> 0 | E47: =+EDITABLE!E49 -> 0 | F47: =+EDITABLE!F49 -> 0 | G47: =+EDITABLE!G49 -> 0 | H47: =+EDITABLE!H49 -> 0 | I47: =+EDITABLE!I49 -> 0 | J47: =+EDITABLE!J49 -> 0 | K47: =+EDITABLE!K49 -> 0 | L47: =+EDITABLE!L49 -> 0
A48: =CONCATENATE(+EDITABLE!C51," ",H48) -> CPU AULA-E2 | B48: =+EDITABLE!A51 -> CPUAULA-E2 | C48: =+EDITABLE!B51 -> 1 | D48: =+EDITABLE!D51 -> NEGRO | E48: =+EDITABLE!E51 -> SION | F48: =+EDITABLE!F51 -> PC-SION-COE I5-SAM20 | G48: =+EDITABLE!G51 -> 81834 | H48: =+EDITABLE!H51 -> AULA-E2 | I48: =+EDITABLE!I51 -> BUENO | J48: =+EDITABLE!J51 -> WINDOWS 8.1 SINGLE LENGUAGE, PROCESADOR: INTEL ® CORE TM i5-4460 CPU, 3.20 GHZ, RAM 4 GB, 64 BITS, INTERNET ALAMBRICO | K48: =+EDITABLE!K51 -> 250 | L48: =+EDITABLE!L51 -> 45288 | M48: 4
A49: =CONCATENATE(+EDITABLE!C52," ",H49) -> MOUSE AULA-E2 | B49: =+EDITABLE!A52 -> MOUSAULA-E2 | C49: =+EDITABLE!B52 -> 1 | D49: =+EDITABLE!D52 -> NEGRO, TRASPARENTE | E49: =+EDITABLE!E52 -> INS | F49: =+EDITABLE!F52 -> S/M | G49: =+EDITABLE!G52 -> S/S | H49: =+EDITABLE!H52 -> AULA-E2 | I49: =+EDITABLE!I52 -> BUENO | J49: =+EDITABLE!J52 -> ALAMBRICO, LED, OPTICO | K49: =+EDITABLE!K52 -> 5 | L49: =+EDITABLE!L52 -> 45288
A50: =CONCATENATE(+EDITABLE!C53," ",H50) -> TECLADO AULA-E2 | B50: =+EDITABLE!A53 -> TECLAULA-E2 | C50: =+EDITABLE!B53 -> 1 | D50: =+EDITABLE!D53 -> NEGRO | E50: =+EDITABLE!E53 -> DELUX | F50: =+EDITABLE!F53 -> K5015 | G50: =+EDITABLE!G53 -> K50151110000601 | H50: =+EDITABLE!H53 -> AULA-E2 | I50: =+EDITABLE!I53 -> BUENO | J50: =+EDITABLE!J53 -> ALAMBRICO, HERGONÓMICO, VARIOS USOS, CONECTOR USB | K50: =+EDITABLE!K53 -> 17 | L50: =+EDITABLE!L53 -> 45288
A51: =CONCATENATE(+EDITABLE!C54," ",H51) -> PROYECTOR AULA-E2 | B51: =+EDITABLE!A54 -> PROYAULA-E2 | C51: =+EDITABLE!B54 -> 1 | D51: =+EDITABLE!D54 -> BLANCO | E51: =+EDITABLE!E54 -> VIEWSONIC | F51: =+EDITABLE!F54 -> PA503S | G51: =+EDITABLE!G54 -> VOR231704316 | H51: =+EDITABLE!H54 -> AULA-E2 | I51: =+EDITABLE!I54 -> BUENO | J51: =+EDITABLE!J54 -> CON PEDESTAL, CABLE HDMI DE 15 m. Y CABLE DE ENERGIA | K51: =+EDITABLE!K54 -> 582.72 | L51: =+EDITABLE!L54 -> 45288
...

Sheet TODO_COD
A12: =+EDITABLE!$A$12 -> CODIGO | B12: =+EDITABLE!$B$12 -> CANTIDAD | C12: =+EDITABLE!$C$12 -> PRODUCTO | D12: =+EDITABLE!$D$12 -> COLOR | E12: =+EDITABLE!$E$12 -> MARCA | F12: =+EDITABLE!$F$12 -> MODELO | G12: =+EDITABLE!$G$12 -> SERIE | H12: =+EDITABLE!$H$12 -> UBICACIÓN | I12: =+EDITABLE!$I$12 -> ESTADO | J12: =+EDITABLE!$J$12 -> CARACTERISTICAS | K12: =+EDITABLE!$K$12 -> COSTO | L12: FECHA
A13: =+EDITABLE!A13 -> CPUAULA-C1 | B13: =+EDITABLE!B13 -> 1 | C13: =+EDITABLE!C13 -> CPU | D13: =+EDITABLE!D13 -> NEGRO | E13: =+EDITABLE!E13 -> INS | F13: =+EDITABLE!F13 -> GENERICO | G13: =+EDITABLE!G13 -> 91225062019 | H13: =+EDITABLE!H13 -> AULA-C1 | ... L13: =+EDITABLE!L13 -> 45288 | M13: 1
A14: =+EDITABLE!A14 -> MONIAULA-C1 | B14: =+EDITABLE!B14 -> 1 | C14: =+EDITABLE!C14 -> MONITOR | D14: =+EDITABLE!D14 -> NEGRO | E14: =+EDITABLE!E14 -> LG | F14: =+EDITABLE!F14 -> 20MK400H-B | G14: =+EDITABLE!G14 -> 911NTHM1T121 | H14: =+EDITABLE!H14 -> AULA-C1 | ... L14: =+EDITABLE!L14 -> 45288
A15: =+EDITABLE!A15 -> MOUSAULA-C1 | B15: =+EDITABLE!B15 -> 1 | C15: =+EDITABLE!C15 -> MOUSE | D15: =+EDITABLE!D15 -> NEGRO | E15: =+EDITABLE!E15 -> GENERICO | F15: =+EDITABLE!F15 -> 5V-100MA | G15: =+EDITABLE!G15 -> S/S | H15: =+EDITABLE!H15 -> AULA-C1 | ... L15: =+EDITABLE!L15 -> 45288
A16: =+EDITABLE!A16 -> TECLAULA-C1 | B16: =+EDITABLE!B16 -> 1 | C16: =+EDITABLE!C16 -> TECLADO | D16: =+EDITABLE!D16 -> NEGRO | E16: =+EDITABLE!E16 -> INS | F16: =+EDITABLE!F16 -> S/M | G16: =+EDITABLE!G16 -> S/S | H16: =+EDITABLE!H16 -> AULA-C1 | ... L16: =+EDITABLE!L16 -> 45288
A17: =+EDITABLE!A17 -> PROYAULA-C1 | B17: =+EDITABLE!B17 -> 1 | C17: =+EDITABLE!C17 -> PROYECTOR | D17: =+EDITABLE!D17 -> NEGRO | E17: =+EDITABLE!E17 -> EPSON | F17: =+EDITABLE!F17 -> POWER LITE S12+ | G17: =+EDITABLE!G17 -> PSPK3401963 | H17: =+EDITABLE!H17 -> AULA-C1 | ... L17: =+EDITABLE!L17 -> 45288
A18: =+EDITABLE!A18 -> PARLAULA-C1 | B18: =+EDITABLE!B18 -> 1 | C18: =+EDITABLE!C18 -> PARLANTES | D18: =+EDITABLE!D18 -> NEGRO | E18: =+EDITABLE!E18 -> KLIP EXTREME | F18: =+EDITABLE!F18 -> KSS-710 | G18: =+EDITABLE!G18 -> 13-11580 | H18: =+EDITABLE!H18 -> AULA-C1 | ... L18: =+EDITABLE!L18 -> 45288
A19: =+EDITABLE!A19 -> CAMAAULA-C1 | B19: =+EDITABLE!B19 -> 1 | C19: =+EDITABLE!C19 -> CAMARA VIDEO VIGILANCIA | D19: =+EDITABLE!D19 -> BLANCO | E19: =+EDITABLE!E19 -> HIKVISION | F19: =+EDITABLE!F19 -> S/M | G19: =+EDITABLE!G19 -> S/S | H19: =+EDITABLE!H19 -> AULA-C1 | ... L19: =+EDITABLE!L19 -> 44841
A20: =+EDITABLE!A20 -> SENSAULA-C1 | B20: =+EDITABLE!B20 -> 1 | C20: =+EDITABLE!C20 -> SENSOR DE ALARMA | D20: =+EDITABLE!D20 -> BLANCO | E20: =+EDITABLE!E20 -> DSC | F20: =+EDITABLE!F20 -> LC-100PI | G20: =+EDITABLE!G20 -> 88030080 | H20: =+EDITABLE!H20 -> AULA-C1 | ... L20: =+EDITABLE!L20 -> 44841
A21: =+EDITABLE!A21 | B21: =+EDITABLE!B21 -> 0 | C21: =+EDITABLE!C21 -> 0 | D21: =+EDITABLE!D21 -> 0 | E21: =+EDITABLE!E21 -> 0 | F21: =+EDITABLE!F21 -> 0 | G21: =+EDITABLE!G21 -> 0 | H21: =+EDITABLE!H21 -> 0 | ... L21: =+EDITABLE!L21 -> 0
A22: =+EDITABLE!A22 | B22: =+EDITABLE!B22 -> 0 | C22: =+EDITABLE!C22 -> 0 | D22: =+EDITABLE!D22 -> 0 | E22: =+EDITABLE!E22 -> 0 | F22: =+EDITABLE!F22 -> 0 | G22: =+EDITABLE!G22 -> 0 | H22: =+EDITABLE!H22 -> 0 | ... L22: =+EDITABLE!L22 -> 0
A23: =+EDITABLE!A23 | B23: =+EDITABLE!B23 -> 0 | C23: =+EDITABLE!C23 -> 0 | D23: =+EDITABLE!D23 -> 0 | E23: =+EDITABLE!E23 -> 0 | F23: =+EDITABLE!F23 -> 0 | G23: =+EDITABLE!G23 -> 0 | H23: =+EDITABLE!H23 -> 0 | ... L23: =+EDITABLE!L23 -> 0
A24: =+EDITABLE!A25 -> CPUAULA-C2 | B24: =+EDITABLE!B25 -> 1 | C24: =+EDITABLE!C25 -> CPU | D24: =+EDITABLE!D25 -> NEGRO | E24: =+EDITABLE!E25 -> INS | F24: =+EDITABLE!F25 -> GENERICO | G24: =+EDITABLE!G25 -> 91225062019 | H24: =+EDITABLE!H25 -> AULA-C2 | ... L24: =+EDITABLE!L25 -> 45288 | M24: 2
A25: =+EDITABLE!A26 -> MONIAULA-C2 | B25: =+EDITABLE!B26 -> 1 | C25: =+EDITABLE!C26 -> MONITOR | D25: =+EDITABLE!D26 -> NEGRO | E25: =+EDITABLE!E26 -> LG | F25: =+EDITABLE!F26 -> 20MK400H-B | G25: =+EDITABLE!G26 -> 911NTNH1S119 | H25: =+EDITABLE!H26 -> AULA-C2 | ... L25: =+EDITABLE!L26 -> 45288
A26: =+EDITABLE!A27 -> MOUSAULA-C2 | B26: =+EDITABLE!B27 -> 1 | C26: =+EDITABLE!C27 -> MOUSE | D26: =+EDITABLE!D27 -> NEGRO | E26: =+EDITABLE!E27 -> GENIUS | F26: =+EDITABLE!F27 -> GM-04011P | G26: =+EDITABLE!G27 -> 124430707394 | H26: =+EDITABLE!H27 -> AULA-C2 | ... L26: =+EDITABLE!L27 -> 45288
A27: =+EDITABLE!A28 -> TECLAULA-C2 | B27: =+EDITABLE!B28 -> 1 | C27: =+EDITABLE!C28 -> TECLADO | D27: =+EDITABLE!D28 -> NEGRO | E27: =+EDITABLE!E28 -> INS | F27: =+EDITABLE!F28 -> S/M | G27: =+EDITABLE!G28 -> S/S | H27: =+EDITABLE!H28 -> AULA-C2 | ... L27: =+EDITABLE!L28 -> 45288
A28: =+EDITABLE!A29 -> PROYAULA-C2 | B28: =+EDITABLE!B29 -> 1 | C28: =+EDITABLE!C29 -> PROYECTOR | D28: =+EDITABLE!D29 -> NEGRO | E28: =+EDITABLE!E29 -> EPSON | F28: =+EDITABLE!F29 -> POWER LITE S12+ | G28: =+EDITABLE!G29 -> PSPK3401919 | H28: =+EDITABLE!H29 -> AULA-C2 | ... L28: =+EDITABLE!L29 -> 45288
A29: =+EDITABLE!A30 -> PARLAULA-C2 | B29: =+EDITABLE!B30 -> 1 | C29: =+EDITABLE!C30 -> PARLANTES | D29: =+EDITABLE!D30 -> NEGRO | E29: =+EDITABLE!E30 -> KLIP EXTREME | F29: =+EDITABLE!F30 -> KSS-710 | G29: =+EDITABLE!G30 -> 13-1158005 | H29: =+EDITABLE!H30 -> AULA-C2 | ... L29: =+EDITABLE!L30 -> 45288
A30: =+EDITABLE!A31 -> CAMAAULA-C2 | B30: =+EDITABLE!B31 -> 1 | C30: =+EDITABLE!C31 -> CAMARA VIDEO VIGILANCIA | D30: =+EDITABLE!D31 -> BLANCO | E30: =+EDITABLE!E31 -> HIKVISION | F30: =+EDITABLE!F31 -> S/M | G30: =+EDITABLE!G31 -> S/S | H30: =+EDITABLE!H31 -> AULA-C2 | ... L30: =+EDITABLE!L31 -> 44841
A31: =+EDITABLE!A32 -> SENSAULA-C2 | B31: =+EDITABLE!B32 -> 1 | C31: =+EDITABLE!C32 -> SENSOR DE ALARMA | D31: =+EDITABLE!D32 -> BLANCO | E31: =+EDITABLE!E32 -> DSC | F31: =+EDITABLE!F32 -> LC-100PI | G31: =+EDITABLE!G32 -> 88030080 | H31: =+EDITABLE!H32 -> AULA-C2 | ... L31: =+EDITABLE!L32 -> 44841
A32: =+EDITABLE!A33 -> SWITAULA-C2 | B32: =+EDITABLE!B33 -> 1 | C32: =+EDITABLE!C33 -> SWITCH DE INTERNET | D32: =+EDITABLE!D33 -> AZUL | E32: =+EDITABLE!E33 -> T-PLINK | F32: =+EDITABLE!F33 -> TN-SG108 | G32: =+EDITABLE!G33 -> 22361E5003891 | H32: =+EDITABLE!H33 -> AULA-C2 | ... L32: =+EDITABLE!L33 -> 45288
A33: =+EDITABLE!A34 -> REGUAULA-C2 | B33: =+EDITABLE!B34 -> 1 | C33: =+EDITABLE!C34 -> REGULADOR DE VOLTAJE | D33: =+EDITABLE!D34 -> NEGRO | E33: =+EDITABLE!E34 -> INS | F33: =+EDITABLE!F34 -> AVR-INS2000VA | G33: =+EDITABLE!G34 -> 19C04206300 | H33: =+EDITABLE!H34 -> AULA-C2 | ... L33: =+EDITABLE!L34 -> 45288
A34: =+EDITABLE!A35 | B34: =+EDITABLE!B35 -> 0 | C34: =+EDITABLE!C35 -> 0 | D34: =+EDITABLE!D35 -> 0 | E34: =+EDITABLE!E35 -> 0 | F34: =+EDITABLE!F35 -> 0 | G34: =+EDITABLE!G35 -> 0 | H34: =+EDITABLE!H35 -> 0 | ... L34: =+EDITABLE!L35 -> 0
B35: =+EDITABLE!B36 -> 0 | C35: =+EDITABLE!C36 -> 0 | D35: =+EDITABLE!D36 -> 0 | E35: =+EDITABLE!E36 -> 0 | F35: =+EDITABLE!F36 -> 0 | G35: =+EDITABLE!G36 -> 0 | H35: =+EDITABLE!H36 -> 0 | I35: =+EDITABLE!I36 -> 0 | ... L35: =+EDITABLE!L36 -> 0
A36: =+EDITABLE!A36 | B36: =+EDITABLE!B37 -> 0 | C36: =+EDITABLE!C37 -> 0 | D36: =+EDITABLE!D37 -> 0 | E36: =+EDITABLE!E37 -> 0 | F36: =+EDITABLE!F37 -> 0 | G36: =+EDITABLE!G37 -> 0 | H36: =+EDITABLE!H37 -> 0 | I36: =+EDITABLE!I37 -> 0 | ... L36: =+EDITABLE!L37 -> 0
A37: =+EDITABLE!A39 -> CPUAULA-C3 | B37: =+EDITABLE!B39 -> 1 | C37: =+EDITABLE!C39 -> CPU | D37: =+EDITABLE!D39 -> NEGRO | E37: =+EDITABLE!E39 -> DELUX | F37: =+EDITABLE!F39 -> S/M | G37: =+EDITABLE!G39 -> S/S | H37: =+EDITABLE!H39 -> AULA-C3 | ... L37: =+EDITABLE!L39 -> 45288 | M37: 3
A38: =+EDITABLE!A40 -> MONIAULA-C3 | B38: =+EDITABLE!B40 -> 1 | C38: =+EDITABLE!C40 -> MONITOR | D38: =+EDITABLE!D40 -> NEGRO | E38: =+EDITABLE!E40 -> HP | F38: =+EDITABLE!F40 -> HPLV1911 | G38: =+EDITABLE!G40 -> 6CM213011T | H38: =+EDITABLE!H40 -> AULA-C3 | ... L38: =+EDITABLE!L40 -> 45288
A39: =+EDITABLE!A41 -> MOUSAULA-C3 | B39: =+EDITABLE!B41 -> 1 | C39: =+EDITABLE!C41 -> MOUSE | D39: =+EDITABLE!D41 -> NEGRO, TRASPARENTE | E39: =+EDITABLE!E41 -> INS | F39: =+EDITABLE!F41 -> S/M | G39: =+EDITABLE!G41 -> S/S | H39: =+EDITABLE!H41 -> AULA-C3 | ... L39: =+EDITABLE!L41 -> 45288
A40: =+EDITABLE!A42 -> TECLAULA-C3 | B40: =+EDITABLE!B42 -> 1 | C40: =+EDITABLE!C42 -> TECLADO | D40: =+EDITABLE!D42 -> NEGRO | E40: =+EDITABLE!E42 -> GENERICO | F40: =+EDITABLE!F42 -> S/M | G40: =+EDITABLE!G42 -> S/S | H40: =+EDITABLE!H42 -> AULA-C3 | ... L40: =+EDITABLE!L42 -> 45288
A41: =+EDITABLE!A43 -> PROYAULA-C3 | B41: =+EDITABLE!B43 -> 1 | C41: =+EDITABLE!C43 -> PROYECTOR | D41: =+EDITABLE!D43 -> NEGRO | E41: =+EDITABLE!E43 -> EPSON | F41: =+EDITABLE!F43 -> POWER LITE S12+ | G41: =+EDITABLE!G43 -> PSPK2308028 | H41: =+EDITABLE!H43 -> AULA-C3 | ... L41: =+EDITABLE!L43 -> 45288
A42: =+EDITABLE!A44 -> PARLAULA-C3 | B42: =+EDITABLE!B44 -> 1 | C42: =+EDITABLE!C44 -> PARLANTES | D42: =+EDITABLE!D44 -> NEGRO | E42: =+EDITABLE!E44 -> KLIP EXTREME | F42: =+EDITABLE!F44 -> KSS-710 | G42: =+EDITABLE!G44 -> 13-11580 | H42: =+EDITABLE!H44 -> AULA-C3 | ... L42: =+EDITABLE!L44 -> 45288
A43: =+EDITABLE!A45 -> CAMAAULA-C3 | B43: =+EDITABLE!B45 -> 1 | C43: =+EDITABLE!C45 -> CAMARA VIDEO VIGILANCIA | D43: =+EDITABLE!D45 -> BLANCO | E43: =+EDITABLE!E45 -> HIKVISION | F43: =+EDITABLE!F45 -> S/M | G43: =+EDITABLE!G45 -> S/S | H43: =+EDITABLE!H45 -> AULA-C3 | ... L43: =+EDITABLE!L45 -> 44841
A44: =+EDITABLE!A46 -> SENSAULA-C3 | B44: =+EDITABLE!B46 -> 1 | C44: =+EDITABLE!C46 -> SENSOR DE ALARMA | D44: =+EDITABLE!D46 -> BLANCO | E44: =+EDITABLE!E46 -> DSC | F44: =+EDITABLE!F46 -> LC-100PI | G44: =+EDITABLE!G46 -> 88030080 | H44: =+EDITABLE!H46 -> AULA-C3 | ... L44: =+EDITABLE!L46 -> 44841
A45: =+EDITABLE!A47 | B45: =+EDITABLE!B47 -> 0 | C45: =+EDITABLE!C47 -> 0 | D45: =+EDITABLE!D47 -> 0 | E45: =+EDITABLE!E47 -> 0 | F45: =+EDITABLE!F47 -> 0 | G45: =+EDITABLE!G47 -> 0 | H45: =+EDITABLE!H47 -> 0 | ... L45: =+EDITABLE!L47 -> 0
B46: =+EDITABLE!B48 -> 0 | C46: =+EDITABLE!C48 -> 0 | D46: =+EDITABLE!D48 -> 0 | E46: =+EDITABLE!E48 -> 0 | F46: =+EDITABLE!F48 -> 0 | G46: =+EDITABLE!G48 -> 0 | H46: =+EDITABLE!H48 -> 0 | I46: =+EDITABLE!I48 -> 0 | ... L46: =+EDITABLE!L48 -> 0
A47: =+EDITABLE!A48 | B47: =+EDITABLE!B49 -> 0 | C47: =+EDITABLE!C49 -> 0 | D47: =+EDITABLE!D49 -> 0 | E47: =+EDITABLE!E49 -> 0 | F47: =+EDITABLE!F49 -> 0 | G47: =+EDITABLE!G49 -> 0 | H47: =+EDITABLE!H49 -> 0 | I47: =+EDITABLE!I49 -> 0 | ... L47: =+EDITABLE!L49 -> 0
A48: =+EDITABLE!A51 -> CPUAULA-E2 | B48: =+EDITABLE!B51 -> 1 | C48: =+EDITABLE!C51 -> CPU | D48: =+EDITABLE!D51 -> NEGRO | E48: =+EDITABLE!E51 -> SION | F48: =+EDITABLE!F51 -> PC-SION-COE I5-SAM20 | G48: =+EDITABLE!G51 -> 81834 | H48: =+EDITABLE!H51 -> AULA-E2 | ... L48: =+EDITABLE!L51 -> 45288 | M48: 4
A49: =+EDITABLE!A52 -> MOUSAULA-E2 | B49: =+EDITABLE!B52 -> 1 | C49: =+EDITABLE!C52 -> MOUSE | D49: =+EDITABLE!D52 -> NEGRO, TRASPARENTE | E49: =+EDITABLE!E52 -> INS | F49: =+EDITABLE!F52 -> S/M | G49: =+EDITABLE!G52 -> S/S | H49: =+EDITABLE!H52 -> AULA-E2 | ... L49: =+EDITABLE!L52 -> 45288
A50: =+EDITABLE!A53 -> TECLAULA-E2 | B50: =+EDITABLE!B53 -> 1 | C50: =+EDITABLE!C53 -> TECLADO | D50: =+EDITABLE!D53 -> NEGRO | E50: =+EDITABLE!E53 -> DELUX | F50: =+EDITABLE!F53 -> K5015 | G50: =+EDITABLE!G53 -> K50151110000601 | H50: =+EDITABLE!H53 -> AULA-E2 | ... L50: =+EDITABLE!L53 -> 45288
A51: =+EDITABLE!A54 -> PROYAULA-E2 | B51: =+EDITABLE!B54 -> 1 | C51: =+EDITABLE!C54 -> PROYECTOR | D51: =+EDITABLE!D54 -> BLANCO | E51: =+EDITABLE!E54 -> VIEWSONIC | F51: =+EDITABLE!F54 -> PA503S | G51: =+EDITABLE!G54 -> VOR231704316 | H51: =+EDITABLE!H54 -> AULA-E2 | ... L51: =+EDITABLE!L54 -> 45288
...

Sheet RESUMEN X AREAS
A8: NRO | B8: UBICACIÓN | C8: COSTO | D8: # EQUIPOS
A9: 1 | B9: =+EDITABLE!H365 -> ASESORÍA TÉCNICA VIAL | C9: =SUM(EDITABLE!K365:K375) -> 1160.44 | D9: 6
A10: 2 | B10: =+EDITABLE!H13 -> AULA-C1 | C10: =SUM(EDITABLE!K13:K23) -> 879.7 | D10: 8
A11: 3 | B11: =+EDITABLE!H25 -> AULA-C2 | C11: =SUM(EDITABLE!K25:K37) -> 917.7 | D11: 10
A12: 4 | B12: =+EDITABLE!H39 -> AULA-C3 | C12: =SUM(EDITABLE!K39:K49) -> 915 | D12: 8
A13: 5 | B13: =+EDITABLE!H65 -> AULA-D1 | C13: =SUM(EDITABLE!K65:K75) -> 1115.97 | D13: 8
A14: 6 | B14: =+EDITABLE!H77 -> AULA-E1 | C14: =SUM(EDITABLE!K77:K86) -> 1090.37 | D14: 7
A15: 7 | B15: =+EDITABLE!H51 -> AULA-E2 | C15: =SUM(EDITABLE!K51:K63) -> 1077.72 | D15: 10
A16: 8 | B16: =+EDITABLE!H88 -> AULA-E3 | C16: =SUM(EDITABLE!K88:K97) -> 929.62 | D16: 7
A17: 9 | B17: =+EDITABLE!H377 -> AULA-MEC | C17: =SUM(EDITABLE!K377:K381) -> 466 | D17: 2
A18: 10 | B18: =+EDITABLE!H403 -> BODEGA GRANDE | C18: =SUM(EDITABLE!K403:K441) -> 971.2 | D18: 37
A19: 11 | B19: =+EDITABLE!H205 -> BODEGA SUMINISTROS | C19: =SUM(EDITABLE!K205:K208) -> 200 | D19: 1
A20: 12 | B20: =+EDITABLE!H337 -> CALLE PRINCIPAL | C20: =SUM(EDITABLE!K337:K341) -> 25 | D20: 2
A21: 13 | B21: =+EDITABLE!H153 -> CONTABILIDAD | C21: =SUM(EDITABLE!K153:K161) -> 816.6 | D21: 6
A22: 14 | B22: =+EDITABLE!H388 -> CUARTO DE RED | C22: =SUM(EDITABLE!K388:K398) -> 4725.19 | D22: 8
A23: 15 | B23: =+EDITABLE!H343 -> FISCALIZACIÓN | C23: =SUM(EDITABLE!K343:K357) -> 943.7 | D23: 12
A24: 16 | B24: =+EDITABLE!H359 -> FUNERARIA | C24: =SUM(EDITABLE!K359:K363) -> 30.74 | D24: 2
A25: 17 | B25: =+EDITABLE!H383 -> HOSTAL | C25: =SUM(EDITABLE!K383:K386) -> 80 | D25: 1
A26: 18 | B26: =+EDITABLE!H210 -> INSPECCIÓN GENERAL | C26: =SUM(EDITABLE!K210:K218) -> 640 | D26: 6
A27: 19 | B27: =+EDITABLE!H235 -> LABORATORIO COMPUTACIÓN | C27: =SUM(EDITABLE!K235:K324) -> 6054 | D27: 87
A28: 20 | B28: =+EDITABLE!H198 -> PASILLO GRADAS | C28: =SUM(EDITABLE!K198:K203) -> 90 | D28: 3
A29: 21 | B29: =+EDITABLE!H189 -> PASILLO OFICINAS | C29: =SUM(EDITABLE!K189:K196) -> 3520.32 | D29: 5
A30: 22 | B30: =+EDITABLE!H326 -> PATIO | C30: =SUM(EDITABLE!K326:K335) -> 175 | D30: 7
A31: 23 | B31: =+EDITABLE!H105 -> PSICOSENSOMÉTRICO 1 | C31: =SUM(EDITABLE!K105:K122) -> 7840 | D31: 15
A32: 24 | B32: =+EDITABLE!H124 -> PSICOSENSOMÉTRICO 2 | C32: =SUM(EDITABLE!K124:K139) -> 15680 | D32: 13
A33: 25 | B33: =+EDITABLE!H99 -> SALON DE ACTOS | C33: =SUM(EDITABLE!K99:K103) -> 105 | D33: 2
A34: 26 | B34: =+EDITABLE!H163 -> SECRETARÍA AACC Y ESCUELA | C34: =SUM(EDITABLE!K163:K187) -> 1981.2 | D34: 22
A35: 27 | B35: =+EDITABLE!H220 -> SECRETARIA GENERAL | C35: =SUM(EDITABLE!K220:K233) -> 2265 | D35: 11
A36: 28 | B36: =+EDITABLE!H141 -> TESORERÍA | C36: =SUM(EDITABLE!K141:K151) -> 1005.6 | D36: 8
B38: TOTAL: | C38: =SUM(C9:C37) -> 55701.07 | D38: =SUM(D9:D37) -> 314
